2017-02-20 14:05:52,795-ERROR-_calcImg:..\..\..\src\opencv\modules\imgproc\src\shapedescr.cpp:799: error: (-201) Number of points should be >= 5
Traceback (most recent call last):
  File "D:\MyProjects\WorkProject\opencv4fiber\geomety\GUI\model\modecv.py", line 95, in _calcImg
    self.eresults = self.classify.find(img)
  File "D:\MyProjects\WorkProject\opencv4fiber\geomety\pattern\classify.py", line 201, in find
    coreResult = PickCircle().run(coreimg)
  File "D:\MyProjects\WorkProject\opencv4fiber\geomety\pattern\pickmethod.py", line 34, in run
    ellipse = cv2.fitEllipse(mergedpoints)
error: ..\..\..\src\opencv\modules\imgproc\src\shapedescr.cpp:799: error: (-201) Number of points should be >= 5

2017-02-20 15:24:45,413-ERROR-_calcImg:
Traceback (most recent call last):
  File "D:\MyProjects\WorkProject\opencv4fiber\geomety\GUI\model\modecv.py", line 95, in _calcImg
    self.eresults = self.classify.find(img)
  File "D:\MyProjects\WorkProject\opencv4fiber\geomety\pattern\classify.py", line 201, in find
    coreResult = PickCircle().run(coreimg)
  File "D:\MyProjects\WorkProject\opencv4fiber\geomety\pattern\pickmethod.py", line 29, in run
    raise ClassCoreError
ClassCoreError
2017-02-23 10:22:44,072-ERROR-_calcImg:
Traceback (most recent call last):
  File "D:\MyProjects\WorkProject\opencv4fiber\geomety\GUI\model\modecv.py", line 95, in _calcImg
    self.eresults = self.classify.find(img)
  File "D:\MyProjects\WorkProject\opencv4fiber\geomety\pattern\classify.py", line 201, in find
    coreResult = PickCircle().run(coreimg)
  File "D:\MyProjects\WorkProject\opencv4fiber\geomety\pattern\pickmethod.py", line 29, in run
    raise ClassCoreError
ClassCoreError
2017-02-23 14:11:10,888-ERROR-_calcImg:
Traceback (most recent call last):
  File "D:\MyProjects\WorkProject\opencv4fiber\geomety\GUI\model\modecv.py", line 95, in _calcImg
    self.eresults = self.classify.find(img)
  File "D:\MyProjects\WorkProject\opencv4fiber\geomety\pattern\classify.py", line 231, in find
    coreResult = PickCircle().run(coreimg)
  File "D:\MyProjects\WorkProject\opencv4fiber\geomety\pattern\pickmethod.py", line 29, in run
    raise ClassCoreError
ClassCoreError
2017-03-06 12:21:14,798-ERROR-_calcImg:
Traceback (most recent call last):
  File "D:\MyProjects\WorkProject\opencv4fiber\geomety\GUI\model\modecv.py", line 93, in _calcImg
    self.eresults = self.classify.find(img)
  File "D:\MyProjects\WorkProject\opencv4fiber\geomety\pattern\classify.py", line 231, in find
    coreResult = PickCircle().run(coreimg)
  File "D:\MyProjects\WorkProject\opencv4fiber\geomety\pattern\pickmethod.py", line 29, in run
    raise ClassCoreError
ClassCoreError
2017-03-06 12:52:16,595-ERROR-_calcImg:
Traceback (most recent call last):
  File "D:\MyProjects\WorkProject\opencv4fiber\geomety\GUI\model\modecv.py", line 93, in _calcImg
    self.eresults = self.classify.find(img)
  File "D:\MyProjects\WorkProject\opencv4fiber\geomety\pattern\classify.py", line 231, in find
    coreResult = PickCircle().run(coreimg)
  File "D:\MyProjects\WorkProject\opencv4fiber\geomety\pattern\pickmethod.py", line 29, in run
    raise ClassCoreError
ClassCoreError
2017-03-06 12:52:47,000-ERROR-_calcImg:
Traceback (most recent call last):
  File "D:\MyProjects\WorkProject\opencv4fiber\geomety\GUI\model\modecv.py", line 93, in _calcImg
    self.eresults = self.classify.find(img)
  File "D:\MyProjects\WorkProject\opencv4fiber\geomety\pattern\classify.py", line 231, in find
    coreResult = PickCircle().run(coreimg)
  File "D:\MyProjects\WorkProject\opencv4fiber\geomety\pattern\pickmethod.py", line 29, in run
    raise ClassCoreError
ClassCoreError
2017-03-06 12:55:43,158-ERROR-_calcImg:
Traceback (most recent call last):
  File "D:\MyProjects\WorkProject\opencv4fiber\geomety\GUI\model\modecv.py", line 93, in _calcImg
    self.eresults = self.classify.find(img)
  File "D:\MyProjects\WorkProject\opencv4fiber\geomety\pattern\classify.py", line 231, in find
    coreResult = PickCircle().run(coreimg)
  File "D:\MyProjects\WorkProject\opencv4fiber\geomety\pattern\pickmethod.py", line 29, in run
    raise ClassCoreError
ClassCoreError
2017-03-06 12:58:14,289-ERROR-_calcImg:
Traceback (most recent call last):
  File "D:\MyProjects\WorkProject\opencv4fiber\geomety\GUI\model\modecv.py", line 93, in _calcImg
    self.eresults = self.classify.find(img)
  File "D:\MyProjects\WorkProject\opencv4fiber\geomety\pattern\classify.py", line 231, in find
    coreResult = PickCircle().run(coreimg)
  File "D:\MyProjects\WorkProject\opencv4fiber\geomety\pattern\pickmethod.py", line 29, in run
    raise ClassCoreError
ClassCoreError
2017-03-06 13:22:50,108-ERROR-_calcImg:
Traceback (most recent call last):
  File "D:\MyProjects\WorkProject\opencv4fiber\geomety\GUI\model\modecv.py", line 93, in _calcImg
    self.eresults = self.classify.find(img)
  File "D:\MyProjects\WorkProject\opencv4fiber\geomety\pattern\classify.py", line 236, in find
    coreResult = PickCircle().run(coreimg)
  File "D:\MyProjects\WorkProject\opencv4fiber\geomety\pattern\pickmethod.py", line 29, in run
    raise ClassCoreError
ClassCoreError
2017-03-06 13:25:38,819-ERROR-_calcImg:
Traceback (most recent call last):
  File "D:\MyProjects\WorkProject\opencv4fiber\geomety\GUI\model\modecv.py", line 93, in _calcImg
    self.eresults = self.classify.find(img)
  File "D:\MyProjects\WorkProject\opencv4fiber\geomety\pattern\classify.py", line 236, in find
    coreResult = PickCircle().run(coreimg)
  File "D:\MyProjects\WorkProject\opencv4fiber\geomety\pattern\pickmethod.py", line 29, in run
    raise ClassCoreError
ClassCoreError
2017-03-06 13:27:51,786-ERROR-_calcImg:unbound method run() must be called with ExtractEdge instance as first argument (got ndarray instance instead)
Traceback (most recent call last):
  File "D:\MyProjects\WorkProject\opencv4fiber\geomety\GUI\model\modecv.py", line 93, in _calcImg
    self.eresults = self.classify.find(img)
  File "D:\MyProjects\WorkProject\opencv4fiber\geomety\pattern\classify.py", line 232, in find
    cladimg = ExtractEdge.run(cladimg)
TypeError: unbound method run() must be called with ExtractEdge instance as first argument (got ndarray instance instead)
2017-03-06 13:28:19,321-ERROR-_calcImg:unbound method run() must be called with ExtractEdge instance as first argument (got ndarray instance instead)
Traceback (most recent call last):
  File "D:\MyProjects\WorkProject\opencv4fiber\geomety\GUI\model\modecv.py", line 93, in _calcImg
    self.eresults = self.classify.find(img)
  File "D:\MyProjects\WorkProject\opencv4fiber\geomety\pattern\classify.py", line 232, in find
    cladimg = ExtractEdge.run(cladimg)
TypeError: unbound method run() must be called with ExtractEdge instance as first argument (got ndarray instance instead)
2017-03-06 13:52:37,111-ERROR-_calcImg:
Traceback (most recent call last):
  File "D:\MyProjects\WorkProject\opencv4fiber\geomety\GUI\model\modecv.py", line 93, in _calcImg
    self.eresults = self.classify.find(img)
  File "D:\MyProjects\WorkProject\opencv4fiber\geomety\pattern\classify.py", line 237, in find
    coreResult = PickCircle().run(coreimg)
  File "D:\MyProjects\WorkProject\opencv4fiber\geomety\pattern\pickmethod.py", line 29, in run
    raise ClassCoreError
ClassCoreError
2017-03-08 20:04:21,648-ERROR-_calcImg:'ascii' codec can't encode characters in position 0-5: ordinal not in range(128)
Traceback (most recent call last):
  File "D:\MyProjects\WorkProject\opencv4fiber\geomety\GUI\model\modecv.py", line 98, in _calcImg
    self._emitCVShowResult(AvgResult(results))
  File "D:\MyProjects\WorkProject\opencv4fiber\geomety\GUI\model\modecv.py", line 179, in _emitCVShowResult
    print 'emit result', text
UnicodeEncodeError: 'ascii' codec can't encode characters in position 0-5: ordinal not in range(128)
2017-03-08 20:04:29,055-ERROR-_calcImg:'ascii' codec can't encode characters in position 0-5: ordinal not in range(128)
Traceback (most recent call last):
  File "D:\MyProjects\WorkProject\opencv4fiber\geomety\GUI\model\modecv.py", line 98, in _calcImg
    self._emitCVShowResult(AvgResult(results))
  File "D:\MyProjects\WorkProject\opencv4fiber\geomety\GUI\model\modecv.py", line 179, in _emitCVShowResult
    print 'emit result', text
UnicodeEncodeError: 'ascii' codec can't encode characters in position 0-5: ordinal not in range(128)
2017-03-08 21:25:46,581-ERROR-_emitCVShowResult:清晰度指数：  12.13
纤芯直径：    211.11
包层直径：    287.65
纤芯不圆度：  0.44
包层不圆度：  0.55
芯包同心度：  10.07
None
2017-03-08 21:29:06,744-ERROR-_emitCVShowResult:清晰度指数：  12.37
纤芯直径：    77.07
包层直径：    103.53
纤芯不圆度：  0.15
包层不圆度：  0.00
芯包同心度：  5.81
None
2017-03-08 21:33:55,759-ERROR-_emitCVShowResult:清晰度指数：  12.08
纤芯直径：    77.06
包层直径：    103.53
纤芯不圆度：  0.16
包层不圆度：  0.06
芯包同心度：  6.03
None
2017-03-08 21:34:08,036-ERROR-_calcImg:[Errno 9] Bad file descriptor
Traceback (most recent call last):
  File "D:\MyProjects\WorkProject\opencv4fiber\geomety\GUI\model\modecv.py", line 96, in _calcImg
    print 'get result', result
IOError: [Errno 9] Bad file descriptor
2017-03-08 21:35:18,940-ERROR-_emitCVShowResult:清晰度指数：  11.98
纤芯直径：    77.06
包层直径：    103.55
纤芯不圆度：  0.15
包层不圆度：  0.14
芯包同心度：  6.08
None
2017-03-08 21:35:26,786-ERROR-_emitCVShowResult:清晰度指数：  11.98
纤芯直径：    77.07
包层直径：    103.54
纤芯不圆度：  0.17
包层不圆度：  0.07
芯包同心度：  6.02
None
2017-03-08 21:35:33,391-ERROR-_emitCVShowResult:清晰度指数：  12.13
纤芯直径：    77.07
包层直径：    103.52
纤芯不圆度：  0.10
包层不圆度：  0.00
芯包同心度：  5.72
None
2017-03-08 21:39:19,161-ERROR-_emitCVShowResult:清晰度指数：  11.98
纤芯直径：    77.05
包层直径：    103.52
纤芯不圆度：  0.18
包层不圆度：  0.00
芯包同心度：  5.74
None
2017-03-08 21:39:27,332-ERROR-_emitCVShowResult:清晰度指数：  12.69
纤芯直径：    77.08
包层直径：    103.52
纤芯不圆度：  0.12
包层不圆度：  0.00
芯包同心度：  5.95
None
2017-03-08 21:40:44,982-ERROR-_emitCVShowResult:清晰度指数：  12.11
纤芯直径：    77.03
包层直径：    103.52
纤芯不圆度：  0.09
包层不圆度：  0.00
芯包同心度：  5.61
None
2017-03-08 21:40:44,983-ERROR-_calcImg:[Errno 9] Bad file descriptor
Traceback (most recent call last):
  File "D:\MyProjects\WorkProject\opencv4fiber\geomety\GUI\model\modecv.py", line 98, in _calcImg
    self._emitCVShowResult(AvgResult(results))
  File "D:\MyProjects\WorkProject\opencv4fiber\geomety\GUI\model\modecv.py", line 184, in _emitCVShowResult
    sys.stdout.flush()
IOError: [Errno 9] Bad file descriptor
2017-03-08 21:40:52,391-ERROR-_emitCVShowResult:清晰度指数：  12.44
纤芯直径：    77.05
包层直径：    103.52
纤芯不圆度：  0.13
包层不圆度：  0.00
芯包同心度：  5.55
None
2017-03-08 21:40:52,391-ERROR-_calcImg:[Errno 9] Bad file descriptor
Traceback (most recent call last):
  File "D:\MyProjects\WorkProject\opencv4fiber\geomety\GUI\model\modecv.py", line 98, in _calcImg
    self._emitCVShowResult(AvgResult(results))
  File "D:\MyProjects\WorkProject\opencv4fiber\geomety\GUI\model\modecv.py", line 184, in _emitCVShowResult
    sys.stdout.flush()
IOError: [Errno 9] Bad file descriptor
2017-03-08 21:40:59,176-ERROR-_emitCVShowResult:清晰度指数：  13.24
纤芯直径：    77.09
包层直径：    103.53
纤芯不圆度：  0.11
包层不圆度：  0.05
芯包同心度：  5.68
None
2017-03-08 21:40:59,176-ERROR-_calcImg:[Errno 9] Bad file descriptor
Traceback (most recent call last):
  File "D:\MyProjects\WorkProject\opencv4fiber\geomety\GUI\model\modecv.py", line 98, in _calcImg
    self._emitCVShowResult(AvgResult(results))
  File "D:\MyProjects\WorkProject\opencv4fiber\geomety\GUI\model\modecv.py", line 184, in _emitCVShowResult
    sys.stdout.flush()
IOError: [Errno 9] Bad file descriptor
2017-03-08 21:41:06,543-ERROR-_emitCVShowResult:清晰度指数：  12.44
纤芯直径：    77.08
包层直径：    103.54
纤芯不圆度：  0.10
包层不圆度：  0.10
芯包同心度：  6.08
None
2017-03-08 21:41:06,543-ERROR-_calcImg:[Errno 9] Bad file descriptor
Traceback (most recent call last):
  File "D:\MyProjects\WorkProject\opencv4fiber\geomety\GUI\model\modecv.py", line 98, in _calcImg
    self._emitCVShowResult(AvgResult(results))
  File "D:\MyProjects\WorkProject\opencv4fiber\geomety\GUI\model\modecv.py", line 184, in _emitCVShowResult
    sys.stdout.flush()
IOError: [Errno 9] Bad file descriptor
2017-03-08 21:41:16,654-ERROR-_emitCVShowResult:清晰度指数：  14.35
纤芯直径：    77.07
包层直径：    103.55
纤芯不圆度：  0.12
包层不圆度：  0.16
芯包同心度：  6.12
None
2017-03-08 21:41:16,655-ERROR-_calcImg:[Errno 9] Bad file descriptor
Traceback (most recent call last):
  File "D:\MyProjects\WorkProject\opencv4fiber\geomety\GUI\model\modecv.py", line 98, in _calcImg
    self._emitCVShowResult(AvgResult(results))
  File "D:\MyProjects\WorkProject\opencv4fiber\geomety\GUI\model\modecv.py", line 184, in _emitCVShowResult
    sys.stdout.flush()
IOError: [Errno 9] Bad file descriptor
2017-03-08 21:41:26,907-ERROR-_emitCVShowResult:清晰度指数：  12.69
纤芯直径：    77.05
包层直径：    103.54
纤芯不圆度：  0.20
包层不圆度：  0.08
芯包同心度：  5.93
None
2017-03-08 21:41:26,907-ERROR-_calcImg:[Errno 9] Bad file descriptor
Traceback (most recent call last):
  File "D:\MyProjects\WorkProject\opencv4fiber\geomety\GUI\model\modecv.py", line 98, in _calcImg
    self._emitCVShowResult(AvgResult(results))
  File "D:\MyProjects\WorkProject\opencv4fiber\geomety\GUI\model\modecv.py", line 184, in _emitCVShowResult
    sys.stdout.flush()
IOError: [Errno 9] Bad file descriptor
2017-03-08 21:41:40,407-ERROR-_emitCVShowResult:清晰度指数：  13.06
纤芯直径：    77.04
包层直径：    103.53
纤芯不圆度：  0.13
包层不圆度：  0.01
芯包同心度：  5.91
None
2017-03-08 21:41:40,407-ERROR-_calcImg:[Errno 9] Bad file descriptor
Traceback (most recent call last):
  File "D:\MyProjects\WorkProject\opencv4fiber\geomety\GUI\model\modecv.py", line 98, in _calcImg
    self._emitCVShowResult(AvgResult(results))
  File "D:\MyProjects\WorkProject\opencv4fiber\geomety\GUI\model\modecv.py", line 184, in _emitCVShowResult
    sys.stdout.flush()
IOError: [Errno 9] Bad file descriptor
2017-03-08 21:41:52,994-ERROR-_emitCVShowResult:清晰度指数：  11.98
纤芯直径：    77.04
包层直径：    103.53
纤芯不圆度：  0.09
包层不圆度：  0.02
芯包同心度：  6.00
None
2017-03-08 21:41:52,994-ERROR-_calcImg:[Errno 9] Bad file descriptor
Traceback (most recent call last):
  File "D:\MyProjects\WorkProject\opencv4fiber\geomety\GUI\model\modecv.py", line 98, in _calcImg
    self._emitCVShowResult(AvgResult(results))
  File "D:\MyProjects\WorkProject\opencv4fiber\geomety\GUI\model\modecv.py", line 184, in _emitCVShowResult
    sys.stdout.flush()
IOError: [Errno 9] Bad file descriptor
2017-03-08 21:42:00,730-ERROR-_emitCVShowResult:清晰度指数：  12.08
纤芯直径：    77.06
包层直径：    103.52
纤芯不圆度：  0.15
包层不圆度：  0.00
芯包同心度：  5.87
None
2017-03-08 21:42:00,730-ERROR-_calcImg:[Errno 9] Bad file descriptor
Traceback (most recent call last):
  File "D:\MyProjects\WorkProject\opencv4fiber\geomety\GUI\model\modecv.py", line 98, in _calcImg
    self._emitCVShowResult(AvgResult(results))
  File "D:\MyProjects\WorkProject\opencv4fiber\geomety\GUI\model\modecv.py", line 184, in _emitCVShowResult
    sys.stdout.flush()
IOError: [Errno 9] Bad file descriptor
2017-03-08 21:47:08,759-ERROR-_emitCVShowResult:清晰度指数：  12.69
纤芯直径：    77.05
包层直径：    103.53
纤芯不圆度：  0.13
包层不圆度：  0.05
芯包同心度：  5.84
None
2017-03-08 21:47:08,762-ERROR-_calcImg:[Errno 9] Bad file descriptor
Traceback (most recent call last):
  File "D:\MyProjects\WorkProject\opencv4fiber\geomety\GUI\model\modecv.py", line 98, in _calcImg
    self._emitCVShowResult(AvgResult(results))
  File "D:\MyProjects\WorkProject\opencv4fiber\geomety\GUI\model\modecv.py", line 184, in _emitCVShowResult
    sys.stdout.flush()
IOError: [Errno 9] Bad file descriptor
2017-03-08 21:47:16,618-ERROR-_emitCVShowResult:清晰度指数：  11.98
纤芯直径：    77.05
包层直径：    103.52
纤芯不圆度：  0.16
包层不圆度：  0.00
芯包同心度：  5.58
None
2017-03-08 21:47:16,618-ERROR-_calcImg:[Errno 9] Bad file descriptor
Traceback (most recent call last):
  File "D:\MyProjects\WorkProject\opencv4fiber\geomety\GUI\model\modecv.py", line 98, in _calcImg
    self._emitCVShowResult(AvgResult(results))
  File "D:\MyProjects\WorkProject\opencv4fiber\geomety\GUI\model\modecv.py", line 184, in _emitCVShowResult
    sys.stdout.flush()
IOError: [Errno 9] Bad file descriptor
2017-03-08 21:47:23,494-ERROR-_emitCVShowResult:清晰度指数：  11.87
纤芯直径：    77.06
包层直径：    103.53
纤芯不圆度：  0.19
包层不圆度：  0.07
芯包同心度：  6.00
None
2017-03-08 21:47:23,494-ERROR-_calcImg:[Errno 9] Bad file descriptor
Traceback (most recent call last):
  File "D:\MyProjects\WorkProject\opencv4fiber\geomety\GUI\model\modecv.py", line 98, in _calcImg
    self._emitCVShowResult(AvgResult(results))
  File "D:\MyProjects\WorkProject\opencv4fiber\geomety\GUI\model\modecv.py", line 184, in _emitCVShowResult
    sys.stdout.flush()
IOError: [Errno 9] Bad file descriptor
2017-03-08 21:47:32,470-ERROR-_emitCVShowResult:清晰度指数：  14.35
纤芯直径：    77.07
包层直径：    103.53
纤芯不圆度：  0.12
包层不圆度：  0.01
芯包同心度：  5.84
None
2017-03-08 21:47:32,470-ERROR-_calcImg:[Errno 9] Bad file descriptor
Traceback (most recent call last):
  File "D:\MyProjects\WorkProject\opencv4fiber\geomety\GUI\model\modecv.py", line 98, in _calcImg
    self._emitCVShowResult(AvgResult(results))
  File "D:\MyProjects\WorkProject\opencv4fiber\geomety\GUI\model\modecv.py", line 184, in _emitCVShowResult
    sys.stdout.flush()
IOError: [Errno 9] Bad file descriptor
2017-03-08 21:47:41,382-ERROR-_emitCVShowResult:清晰度指数：  12.11
纤芯直径：    77.09
包层直径：    103.52
纤芯不圆度：  0.10
包层不圆度：  0.00
芯包同心度：  5.79
None
2017-03-08 21:47:41,382-ERROR-_calcImg:[Errno 9] Bad file descriptor
Traceback (most recent call last):
  File "D:\MyProjects\WorkProject\opencv4fiber\geomety\GUI\model\modecv.py", line 98, in _calcImg
    self._emitCVShowResult(AvgResult(results))
  File "D:\MyProjects\WorkProject\opencv4fiber\geomety\GUI\model\modecv.py", line 184, in _emitCVShowResult
    sys.stdout.flush()
IOError: [Errno 9] Bad file descriptor
2017-03-08 21:47:48,742-ERROR-_emitCVShowResult:清晰度指数：  12.44
纤芯直径：    77.03
包层直径：    103.54
纤芯不圆度：  0.12
包层不圆度：  0.08
芯包同心度：  6.05
None
2017-03-08 21:47:48,742-ERROR-_calcImg:[Errno 9] Bad file descriptor
Traceback (most recent call last):
  File "D:\MyProjects\WorkProject\opencv4fiber\geomety\GUI\model\modecv.py", line 98, in _calcImg
    self._emitCVShowResult(AvgResult(results))
  File "D:\MyProjects\WorkProject\opencv4fiber\geomety\GUI\model\modecv.py", line 184, in _emitCVShowResult
    sys.stdout.flush()
IOError: [Errno 9] Bad file descriptor
2017-03-08 21:47:56,596-ERROR-_emitCVShowResult:清晰度指数：  12.10
纤芯直径：    77.06
包层直径：    103.53
纤芯不圆度：  0.12
包层不圆度：  0.05
芯包同心度：  5.93
None
2017-03-08 21:47:56,596-ERROR-_calcImg:[Errno 9] Bad file descriptor
Traceback (most recent call last):
  File "D:\MyProjects\WorkProject\opencv4fiber\geomety\GUI\model\modecv.py", line 98, in _calcImg
    self._emitCVShowResult(AvgResult(results))
  File "D:\MyProjects\WorkProject\opencv4fiber\geomety\GUI\model\modecv.py", line 184, in _emitCVShowResult
    sys.stdout.flush()
IOError: [Errno 9] Bad file descriptor
2017-03-08 21:48:16,759-ERROR-_emitCVShowResult:清晰度指数：  13.24
纤芯直径：    77.06
包层直径：    103.53
纤芯不圆度：  0.15
包层不圆度：  0.00
芯包同心度：  5.89
None
2017-03-08 21:48:16,759-ERROR-_calcImg:[Errno 9] Bad file descriptor
Traceback (most recent call last):
  File "D:\MyProjects\WorkProject\opencv4fiber\geomety\GUI\model\modecv.py", line 98, in _calcImg
    self._emitCVShowResult(AvgResult(results))
  File "D:\MyProjects\WorkProject\opencv4fiber\geomety\GUI\model\modecv.py", line 184, in _emitCVShowResult
    sys.stdout.flush()
IOError: [Errno 9] Bad file descriptor
2017-03-08 21:48:57,071-ERROR-_emitCVShowResult:清晰度指数：  13.24
纤芯直径：    77.06
包层直径：    103.53
纤芯不圆度：  0.14
包层不圆度：  0.07
芯包同心度：  6.01
None
2017-03-08 21:48:57,071-ERROR-_calcImg:[Errno 9] Bad file descriptor
Traceback (most recent call last):
  File "D:\MyProjects\WorkProject\opencv4fiber\geomety\GUI\model\modecv.py", line 98, in _calcImg
    self._emitCVShowResult(AvgResult(results))
  File "D:\MyProjects\WorkProject\opencv4fiber\geomety\GUI\model\modecv.py", line 184, in _emitCVShowResult
    sys.stdout.flush()
IOError: [Errno 9] Bad file descriptor
2017-03-08 21:50:40,174-ERROR-_emitCVShowResult:清晰度指数：  12.37
纤芯直径：    77.08
包层直径：    103.53
纤芯不圆度：  0.12
包层不圆度：  0.05
芯包同心度：  6.02
None
2017-03-08 21:50:40,174-ERROR-_calcImg:[Errno 9] Bad file descriptor
Traceback (most recent call last):
  File "D:\MyProjects\WorkProject\opencv4fiber\geomety\GUI\model\modecv.py", line 98, in _calcImg
    self._emitCVShowResult(AvgResult(results))
  File "D:\MyProjects\WorkProject\opencv4fiber\geomety\GUI\model\modecv.py", line 184, in _emitCVShowResult
    sys.stdout.flush()
IOError: [Errno 9] Bad file descriptor
2017-03-08 21:53:59,467-ERROR-_emitCVShowResult:清晰度指数：  11.98
纤芯直径：    77.04
包层直径：    103.53
纤芯不圆度：  0.13
包层不圆度：  0.06
芯包同心度：  5.69
None
2017-03-08 21:53:59,467-ERROR-_calcImg:[Errno 9] Bad file descriptor
Traceback (most recent call last):
  File "D:\MyProjects\WorkProject\opencv4fiber\geomety\GUI\model\modecv.py", line 98, in _calcImg
    self._emitCVShowResult(AvgResult(results))
  File "D:\MyProjects\WorkProject\opencv4fiber\geomety\GUI\model\modecv.py", line 184, in _emitCVShowResult
    sys.stdout.flush()
IOError: [Errno 9] Bad file descriptor
2017-03-08 21:54:06,586-ERROR-_emitCVShowResult:清晰度指数：  11.87
纤芯直径：    77.04
包层直径：    103.55
纤芯不圆度：  0.17
包层不圆度：  0.14
芯包同心度：  6.00
None
2017-03-08 21:54:06,586-ERROR-_calcImg:[Errno 9] Bad file descriptor
Traceback (most recent call last):
  File "D:\MyProjects\WorkProject\opencv4fiber\geomety\GUI\model\modecv.py", line 98, in _calcImg
    self._emitCVShowResult(AvgResult(results))
  File "D:\MyProjects\WorkProject\opencv4fiber\geomety\GUI\model\modecv.py", line 184, in _emitCVShowResult
    sys.stdout.flush()
IOError: [Errno 9] Bad file descriptor
2017-03-08 21:59:43,456-ERROR-_calcImg:
Traceback (most recent call last):
  File "D:\MyProjects\WorkProject\opencv4fiber\geomety\GUI\model\modecv.py", line 94, in _calcImg
    self.eresults = self.classify.find(img)
  File "D:\MyProjects\WorkProject\opencv4fiber\geomety\pattern\classify.py", line 237, in find
    coreResult = PickCircle().run(coreimg)
  File "D:\MyProjects\WorkProject\opencv4fiber\geomety\pattern\pickmethod.py", line 29, in run
    raise ClassCoreError
ClassCoreError
2017-03-08 22:02:28,382-ERROR-_calcImg:
Traceback (most recent call last):
  File "D:\MyProjects\WorkProject\opencv4fiber\geomety\GUI\model\modecv.py", line 94, in _calcImg
    self.eresults = self.classify.find(img)
  File "D:\MyProjects\WorkProject\opencv4fiber\geomety\pattern\classify.py", line 237, in find
    coreResult = PickCircle().run(coreimg)
  File "D:\MyProjects\WorkProject\opencv4fiber\geomety\pattern\pickmethod.py", line 29, in run
    raise ClassCoreError
ClassCoreError
2017-03-08 22:03:11,095-ERROR-_calcImg:
Traceback (most recent call last):
  File "D:\MyProjects\WorkProject\opencv4fiber\geomety\GUI\model\modecv.py", line 94, in _calcImg
    self.eresults = self.classify.find(img)
  File "D:\MyProjects\WorkProject\opencv4fiber\geomety\pattern\classify.py", line 237, in find
    coreResult = PickCircle().run(coreimg)
  File "D:\MyProjects\WorkProject\opencv4fiber\geomety\pattern\pickmethod.py", line 29, in run
    raise ClassCoreError
ClassCoreError
2017-03-08 22:04:08,447-ERROR-_calcImg:
Traceback (most recent call last):
  File "D:\MyProjects\WorkProject\opencv4fiber\geomety\GUI\model\modecv.py", line 94, in _calcImg
    self.eresults = self.classify.find(img)
  File "D:\MyProjects\WorkProject\opencv4fiber\geomety\pattern\classify.py", line 239, in find
    coreResult = PickCircle().run(coreimg)
  File "D:\MyProjects\WorkProject\opencv4fiber\geomety\pattern\pickmethod.py", line 29, in run
    raise ClassCoreError
ClassCoreError
2017-03-08 22:04:33,088-ERROR-_calcImg:
Traceback (most recent call last):
  File "D:\MyProjects\WorkProject\opencv4fiber\geomety\GUI\model\modecv.py", line 94, in _calcImg
    self.eresults = self.classify.find(img)
  File "D:\MyProjects\WorkProject\opencv4fiber\geomety\pattern\classify.py", line 239, in find
    coreResult = PickCircle().run(coreimg)
  File "D:\MyProjects\WorkProject\opencv4fiber\geomety\pattern\pickmethod.py", line 29, in run
    raise ClassCoreError
ClassCoreError
2017-03-08 22:04:56,084-ERROR-_calcImg:
Traceback (most recent call last):
  File "D:\MyProjects\WorkProject\opencv4fiber\geomety\GUI\model\modecv.py", line 94, in _calcImg
    self.eresults = self.classify.find(img)
  File "D:\MyProjects\WorkProject\opencv4fiber\geomety\pattern\classify.py", line 239, in find
    coreResult = PickCircle().run(coreimg)
  File "D:\MyProjects\WorkProject\opencv4fiber\geomety\pattern\pickmethod.py", line 29, in run
    raise ClassCoreError
ClassCoreError
2017-03-08 22:05:16,612-ERROR-_calcImg:
Traceback (most recent call last):
  File "D:\MyProjects\WorkProject\opencv4fiber\geomety\GUI\model\modecv.py", line 94, in _calcImg
    self.eresults = self.classify.find(img)
  File "D:\MyProjects\WorkProject\opencv4fiber\geomety\pattern\classify.py", line 239, in find
    coreResult = PickCircle().run(coreimg)
  File "D:\MyProjects\WorkProject\opencv4fiber\geomety\pattern\pickmethod.py", line 29, in run
    raise ClassCoreError
ClassCoreError
2017-03-08 22:06:07,209-ERROR-_calcImg:
Traceback (most recent call last):
  File "D:\MyProjects\WorkProject\opencv4fiber\geomety\GUI\model\modecv.py", line 95, in _calcImg
    self.eresults = self.classify.find(img)
  File "D:\MyProjects\WorkProject\opencv4fiber\geomety\pattern\classify.py", line 239, in find
    coreResult = PickCircle().run(coreimg)
  File "D:\MyProjects\WorkProject\opencv4fiber\geomety\pattern\pickmethod.py", line 29, in run
    raise ClassCoreError
ClassCoreError
2017-03-08 22:07:05,216-ERROR-_calcImg:
Traceback (most recent call last):
  File "D:\MyProjects\WorkProject\opencv4fiber\geomety\GUI\model\modecv.py", line 95, in _calcImg
    self.eresults = self.classify.find(img)
  File "D:\MyProjects\WorkProject\opencv4fiber\geomety\pattern\classify.py", line 240, in find
    coreResult = PickCircle().run(coreimg)
  File "D:\MyProjects\WorkProject\opencv4fiber\geomety\pattern\pickmethod.py", line 29, in run
    raise ClassCoreError
ClassCoreError
2017-03-08 22:07:25,355-ERROR-_calcImg:
Traceback (most recent call last):
  File "D:\MyProjects\WorkProject\opencv4fiber\geomety\GUI\model\modecv.py", line 95, in _calcImg
    self.eresults = self.classify.find(img)
  File "D:\MyProjects\WorkProject\opencv4fiber\geomety\pattern\classify.py", line 240, in find
    coreResult = PickCircle().run(coreimg)
  File "D:\MyProjects\WorkProject\opencv4fiber\geomety\pattern\pickmethod.py", line 29, in run
    raise ClassCoreError
ClassCoreError
2017-03-08 22:07:49,463-ERROR-_calcImg:
Traceback (most recent call last):
  File "D:\MyProjects\WorkProject\opencv4fiber\geomety\GUI\model\modecv.py", line 95, in _calcImg
    self.eresults = self.classify.find(img)
  File "D:\MyProjects\WorkProject\opencv4fiber\geomety\pattern\classify.py", line 240, in find
    coreResult = PickCircle().run(coreimg)
  File "D:\MyProjects\WorkProject\opencv4fiber\geomety\pattern\pickmethod.py", line 29, in run
    raise ClassCoreError
ClassCoreError
2017-03-09 11:33:20,572-ERROR-_emitCVShowResult:清晰度指数：  3.44
纤芯直径：    8.97
包层直径：    124.39
纤芯不圆度：  0.03
包层不圆度：  0.76
芯包同心度：  0.29
None
2017-03-15 14:14:08,657-ERROR-_emitCVShowResult:清晰度指数：  3.49
纤芯直径：    8.97
包层直径：    124.39
纤芯不圆度：  0.03
包层不圆度：  0.76
芯包同心度：  0.29
None
2017-03-15 14:14:20,094-ERROR-_emitCVShowResult:清晰度指数：  3.44
纤芯直径：    8.99
包层直径：    124.31
纤芯不圆度：  0.06
包层不圆度：  0.72
芯包同心度：  0.28
None
2017-03-15 15:49:55,696-ERROR-_emitCVShowResult:清晰度指数：  3.46
纤芯直径：    8.97
包层直径：    124.40
纤芯不圆度：  0.03
包层不圆度：  0.76
芯包同心度：  0.29
None
2017-03-15 15:50:37,734-ERROR-_emitCVShowResult:清晰度指数：  3.46
纤芯直径：    8.98
包层直径：    124.38
纤芯不圆度：  0.01
包层不圆度：  0.75
芯包同心度：  0.29
None
2017-03-15 15:50:47,339-ERROR-_emitCVShowResult:清晰度指数：  3.50
纤芯直径：    8.98
包层直径：    124.39
纤芯不圆度：  0.02
包层不圆度：  0.76
芯包同心度：  0.29
None
2017-03-16 08:55:32,881-ERROR-_emitCVShowResult:清晰度指数：  3.46
纤芯直径：    8.97
包层直径：    124.40
纤芯不圆度：  0.03
包层不圆度：  0.76
芯包同心度：  0.30
None
2017-03-16 09:00:47,493-ERROR-_emitCVShowResult:清晰度指数：  3.44
纤芯直径：    9.00
包层直径：    124.30
纤芯不圆度：  0.05
包层不圆度：  0.72
芯包同心度：  0.28
None
2017-03-16 09:01:09,170-ERROR-_emitCVShowResult:清晰度指数：  3.49
纤芯直径：    8.98
包层直径：    124.38
纤芯不圆度：  0.02
包层不圆度：  0.76
芯包同心度：  0.28
None
2017-03-16 09:01:17,483-ERROR-_emitCVShowResult:清晰度指数：  3.49
纤芯直径：    8.97
包层直径：    124.39
纤芯不圆度：  0.01
包层不圆度：  0.76
芯包同心度：  0.29
None
2017-03-17 13:29:57,569-ERROR-_emitCVShowResult:清晰度指数：  3.46
纤芯直径：    9.00
包层直径：    124.30
纤芯不圆度：  0.05
包层不圆度：  0.72
芯包同心度：  0.27
None
2017-03-17 13:32:37,210-ERROR-_emitCVShowResult:清晰度指数：  3.45
纤芯直径：    8.98
包层直径：    124.39
纤芯不圆度：  0.01
包层不圆度：  0.76
芯包同心度：  0.29
None
2017-03-17 13:32:44,538-ERROR-_emitCVShowResult:清晰度指数：  3.46
纤芯直径：    9.00
包层直径：    124.30
纤芯不圆度：  0.06
包层不圆度：  0.72
芯包同心度：  0.27
None
2017-03-17 13:32:52,776-ERROR-_emitCVShowResult:清晰度指数：  3.49
纤芯直径：    8.97
包层直径：    124.38
纤芯不圆度：  0.02
包层不圆度：  0.76
芯包同心度：  0.29
None
2017-03-17 13:36:37,753-ERROR-_emitCVShowResult:清晰度指数：  3.44
纤芯直径：    8.97
包层直径：    124.40
纤芯不圆度：  0.03
包层不圆度：  0.76
芯包同心度：  0.29
None
2017-03-17 13:53:15,190-ERROR-__del__:Future exception was never retrieved: Traceback (most recent call last):
  File "C:\Anaconda3\envs\cv2\lib\site-packages\tornado\gen.py", line 1024, in run
    yielded = self.gen.send(value)
  File "D:\MyProjects\WorkProject\opencv4fiber\geomety\imgserver\server.py", line 99, in _getImgOnce
    img = img.tobytes() + b'\n\r\n\r'
AttributeError: 'NoneType' object has no attribute 'tobytes'
2017-03-17 14:04:46,653-ERROR-__del__:Future exception was never retrieved: Traceback (most recent call last):
  File "C:\Anaconda3\envs\cv2\lib\site-packages\tornado\gen.py", line 1021, in run
    yielded = self.gen.throw(*exc_info)
  File "D:\MyProjects\WorkProject\opencv4fiber\geomety\imgserver\server.py", line 98, in _getImgOnce
    img = yield self._getImgMethod(self.PARA[0],self.PARA[1])
  File "C:\Anaconda3\envs\cv2\lib\site-packages\tornado\gen.py", line 1015, in run
    value = future.result()
  File "C:\Anaconda3\envs\cv2\lib\site-packages\tornado\concurrent.py", line 237, in result
    raise_exc_info(self._exc_info)
  File "C:\Anaconda3\envs\cv2\lib\site-packages\tornado\gen.py", line 270, in wrapper
    result = func(*args, **kwargs)
  File "D:\MyProjects\WorkProject\opencv4fiber\geomety\imgserver\server.py", line 106, in _getImgMethod
    return randomImg(para)
  File "D:\MyProjects\WorkProject\opencv4fiber\geomety\imgserver\methods.py", line 71, in randomImg
    img = GetImage().get(choice(dirlist),colour='color')
  File "D:\MyProjects\WorkProject\opencv4fiber\geomety\imgserver\methods.py", line 21, in get
    self.singleFileFind(dir_,colour)
  File "D:\MyProjects\WorkProject\opencv4fiber\geomety\imgserver\methods.py", line 41, in singleFileFind
    self._getColorImg(colour = colour)
  File "D:\MyProjects\WorkProject\opencv4fiber\geomety\imgserver\methods.py", line 53, in _getColorImg
    self.img = cv2.cvtColor(self.img, cv2.COLOR_BGR2RGB)
error: ..\..\..\src\opencv\modules\imgproc\src\color.cpp:3346: error: (-215) scn == 3 || scn == 4
2017-03-24 09:57:29,528-ERROR-_emitCVShowResult:清晰度指数：  3.45
纤芯直径：    8.98
包层直径：    124.39
纤芯不圆度：  0.02
包层不圆度：  0.76
芯包同心度：  0.28
None
2017-03-24 09:57:36,540-ERROR-_emitCVShowResult:清晰度指数：  3.44
纤芯直径：    8.98
包层直径：    124.38
纤芯不圆度：  0.02
包层不圆度：  0.75
芯包同心度：  0.29
None
2017-03-24 09:57:44,466-ERROR-_emitCVShowResult:清晰度指数：  3.45
纤芯直径：    8.97
包层直径：    124.39
纤芯不圆度：  0.01
包层不圆度：  0.76
芯包同心度：  0.29
None
2017-03-24 09:57:51,118-ERROR-_emitCVShowResult:清晰度指数：  3.49
纤芯直径：    8.98
包层直径：    124.37
纤芯不圆度：  0.01
包层不圆度：  0.75
芯包同心度：  0.28
None
2017-03-24 09:57:57,753-ERROR-_emitCVShowResult:清晰度指数：  3.50
纤芯直径：    8.97
包层直径：    124.39
纤芯不圆度：  0.03
包层不圆度：  0.76
芯包同心度：  0.29
None
2017-03-24 09:58:06,677-ERROR-_emitCVShowResult:清晰度指数：  3.46
纤芯直径：    8.99
包层直径：    124.31
纤芯不圆度：  0.06
包层不圆度：  0.72
芯包同心度：  0.28
None
2017-03-24 09:58:13,322-ERROR-_emitCVShowResult:清晰度指数：  3.46
纤芯直径：    8.98
包层直径：    124.38
纤芯不圆度：  0.01
包层不圆度：  0.75
芯包同心度：  0.28
None
2017-03-24 09:58:20,098-ERROR-_emitCVShowResult:清晰度指数：  3.44
纤芯直径：    8.97
包层直径：    124.39
纤芯不圆度：  0.02
包层不圆度：  0.76
芯包同心度：  0.29
None
2017-03-24 09:58:26,619-ERROR-_emitCVShowResult:清晰度指数：  3.44
纤芯直径：    9.00
包层直径：    124.30
纤芯不圆度：  0.06
包层不圆度：  0.72
芯包同心度：  0.28
None
2017-03-24 09:58:33,750-ERROR-_emitCVShowResult:清晰度指数：  3.46
纤芯直径：    8.97
包层直径：    124.39
纤芯不圆度：  0.03
包层不圆度：  0.76
芯包同心度：  0.29
None
2017-03-24 12:23:16,447-ERROR-_emitCVShowResult:清晰度指数：  3.50
纤芯直径：    8.98
包层直径：    124.38
纤芯不圆度：  0.03
包层不圆度：  0.75
芯包同心度：  0.28
None
2017-03-24 12:27:14,017-ERROR-_emitCVShowResult:清晰度指数：  3.49
纤芯直径：    8.97
包层直径：    124.40
纤芯不圆度：  0.03
包层不圆度：  0.76
芯包同心度：  0.30
None
2017-03-24 12:29:49,009-ERROR-_emitCVShowResult:清晰度指数：  3.44
纤芯直径：    8.98
包层直径：    124.39
纤芯不圆度：  0.03
包层不圆度：  0.76
芯包同心度：  0.29
None
2017-03-24 12:30:00,434-ERROR-_emitCVShowResult:清晰度指数：  3.45
纤芯直径：    8.98
包层直径：    124.38
纤芯不圆度：  0.01
包层不圆度：  0.75
芯包同心度：  0.28
None
2017-03-24 12:44:38,012-ERROR-_emitCVShowResult:清晰度指数：  3.50
纤芯直径：    8.98
包层直径：    124.37
纤芯不圆度：  0.02
包层不圆度：  0.75
芯包同心度：  0.28
None
2017-03-24 14:40:25,739-ERROR-_emitCVShowResult:清晰度指数：  3.46
纤芯直径：    8.98
包层直径：    124.38
纤芯不圆度：  0.01
包层不圆度：  0.75
芯包同心度：  0.29
None
2017-03-31 09:46:52,247-ERROR-_emitCVShowResult:清晰度指数：  5.92
纤芯直径：    11.88
包层直径：    168.01
纤芯不圆度：  0.51
包层不圆度：  2.28
芯包同心度：  1.10
None
2017-03-31 09:47:23,112-ERROR-_emitCVShowResult:清晰度指数：  5.87
纤芯直径：    11.86
包层直径：    168.21
纤芯不圆度：  0.47
包层不圆度：  2.22
芯包同心度：  1.14
None
2017-03-31 09:47:55,355-ERROR-_emitCVShowResult:清晰度指数：  5.70
纤芯直径：    11.81
包层直径：    167.89
纤芯不圆度：  0.49
包层不圆度：  2.52
芯包同心度：  1.07
None
2017-03-31 09:50:11,177-ERROR-_emitCVShowResult:清晰度指数：  5.64
纤芯直径：    11.85
包层直径：    166.94
纤芯不圆度：  0.50
包层不圆度：  6.13
芯包同心度：  0.46
None
2017-03-31 09:50:56,219-ERROR-_emitCVShowResult:清晰度指数：  6.55
纤芯直径：    13.05
包层直径：    166.95
纤芯不圆度：  0.46
包层不圆度：  3.79
芯包同心度：  0.96
None
2017-03-31 09:52:22,609-ERROR-_emitCVShowResult:清晰度指数：  8.40
纤芯直径：    13.70
包层直径：    194.51
纤芯不圆度：  0.18
包层不圆度：  3.48
芯包同心度：  1.47
None
2017-03-31 09:52:42,089-ERROR-_emitCVShowResult:清晰度指数：  8.79
纤芯直径：    12.01
包层直径：    136.53
纤芯不圆度：  0.43
包层不圆度：  6.83
芯包同心度：  0.20
None
2017-03-31 09:56:44,293-ERROR-_emitCVShowResult:清晰度指数：  4.22
纤芯直径：    8.67
包层直径：    120.14
纤芯不圆度：  0.17
包层不圆度：  2.14
芯包同心度：  0.38
None
2017-03-31 09:57:00,618-ERROR-_emitCVShowResult:清晰度指数：  4.21
纤芯直径：    8.70
包层直径：    120.99
纤芯不圆度：  0.18
包层不圆度：  2.93
芯包同心度：  0.33
None
2017-03-31 09:58:07,096-ERROR-_emitCVShowResult:清晰度指数：  4.36
纤芯直径：    8.70
包层直径：    122.69
纤芯不圆度：  0.18
包层不圆度：  7.14
芯包同心度：  0.61
None
2017-03-31 09:58:34,061-ERROR-_emitCVShowResult:清晰度指数：  4.45
纤芯直径：    10.34
包层直径：    145.24
纤芯不圆度：  0.19
包层不圆度：  8.11
芯包同心度：  0.74
None
2017-03-31 09:58:55,561-ERROR-_emitCVShowResult:清晰度指数：  4.02
纤芯直径：    10.35
包层直径：    142.14
纤芯不圆度：  0.22
包层不圆度：  2.37
芯包同心度：  0.33
None
2017-03-31 09:59:36,963-ERROR-_emitCVShowResult:清晰度指数：  3.98
纤芯直径：    9.53
包层直径：    131.05
纤芯不圆度：  0.20
包层不圆度：  2.15
芯包同心度：  0.35
None
2017-03-31 10:00:25,380-ERROR-_emitCVShowResult:清晰度指数：  3.89
纤芯直径：    8.99
包层直径：    123.34
纤芯不圆度：  0.18
包层不圆度：  2.08
芯包同心度：  0.30
None
2017-03-31 10:01:02,437-ERROR-_emitCVShowResult:清晰度指数：  4.03
纤芯直径：    8.92
包层直径：    123.33
纤芯不圆度：  0.17
包层不圆度：  2.12
芯包同心度：  0.33
None
2017-04-01 10:04:31,466-ERROR-_emitCVShowResult:清晰度指数：  3.45
纤芯直径：    12.12
包层直径：    167.96
纤芯不圆度：  0.03
包层不圆度：  1.02
芯包同心度：  0.39
None
2017-04-01 10:12:25,471-ERROR-_emitCVShowResult:清晰度指数：  3.46
纤芯直径：    8.97
包层直径：    124.40
纤芯不圆度：  0.03
包层不圆度：  0.76
芯包同心度：  0.29
None
2017-04-01 10:16:07,651-ERROR-_emitCVShowResult:清晰度指数：  6.95
纤芯直径：    62.35
包层直径：    116.17
纤芯不圆度：  1.16
包层不圆度：  1.41
芯包同心度：  0.26
None
2017-04-01 10:16:21,816-ERROR-_emitCVShowResult:清晰度指数：  7.01
纤芯直径：    62.33
包层直径：    116.16
纤芯不圆度：  1.08
包层不圆度：  1.46
芯包同心度：  0.26
None
2017-04-01 10:17:54,890-ERROR-_emitCVShowResult:清晰度指数：  6.89
纤芯直径：    62.35
包层直径：    116.17
纤芯不圆度：  1.16
包层不圆度：  1.41
芯包同心度：  0.26
None
2017-04-01 10:18:12,134-ERROR-_emitCVShowResult:清晰度指数：  6.88
纤芯直径：    62.32
包层直径：    116.16
纤芯不圆度：  0.98
包层不圆度：  1.43
芯包同心度：  0.29
None
2017-04-01 10:18:23,240-ERROR-_emitCVShowResult:清晰度指数：  6.83
纤芯直径：    62.31
包层直径：    116.17
纤芯不圆度：  1.03
包层不圆度：  1.45
芯包同心度：  0.27
None
2017-04-01 10:18:43,763-ERROR-_emitCVShowResult:清晰度指数：  6.89
纤芯直径：    62.32
包层直径：    116.16
纤芯不圆度：  1.08
包层不圆度：  1.44
芯包同心度：  0.27
None
2017-04-01 10:18:52,615-ERROR-_emitCVShowResult:清晰度指数：  6.89
纤芯直径：    62.33
包层直径：    116.16
纤芯不圆度：  1.10
包层不圆度：  1.44
芯包同心度：  0.26
None
2017-04-01 10:19:03,201-ERROR-_emitCVShowResult:清晰度指数：  7.01
纤芯直径：    62.31
包层直径：    116.17
纤芯不圆度：  1.05
包层不圆度：  1.43
芯包同心度：  0.27
None
2017-04-01 10:19:12,167-ERROR-_emitCVShowResult:清晰度指数：  6.88
纤芯直径：    62.36
包层直径：    116.16
纤芯不圆度：  1.19
包层不圆度：  1.43
芯包同心度：  0.24
None
2017-04-01 10:19:43,963-ERROR-_emitCVShowResult:清晰度指数：  6.89
纤芯直径：    62.31
包层直径：    116.17
纤芯不圆度：  1.01
包层不圆度：  1.44
芯包同心度：  0.29
None
2017-04-01 10:19:51,891-ERROR-_emitCVShowResult:清晰度指数：  6.91
纤芯直径：    62.32
包层直径：    116.16
纤芯不圆度：  1.06
包层不圆度：  1.46
芯包同心度：  0.27
None
2017-04-01 10:19:59,747-ERROR-_emitCVShowResult:清晰度指数：  6.91
纤芯直径：    62.34
包层直径：    116.16
纤芯不圆度：  1.10
包层不圆度：  1.43
芯包同心度：  0.26
None
2017-04-01 10:20:07,822-ERROR-_emitCVShowResult:清晰度指数：  6.88
纤芯直径：    62.29
包层直径：    116.16
纤芯不圆度：  0.93
包层不圆度：  1.47
芯包同心度：  0.30
None
2017-04-01 10:28:13,857-ERROR-_emitCVShowResult:清晰度指数：  6.94
纤芯直径：    62.31
包层直径：    116.17
纤芯不圆度：  1.01
包层不圆度：  1.42
芯包同心度：  0.28
None
2017-04-01 10:28:20,660-ERROR-_emitCVShowResult:清晰度指数：  6.83
纤芯直径：    62.35
包层直径：    116.17
纤芯不圆度：  1.13
包层不圆度：  1.39
芯包同心度：  0.26
None
2017-04-01 10:28:27,497-ERROR-_emitCVShowResult:清晰度指数：  6.93
纤芯直径：    62.29
包层直径：    116.17
纤芯不圆度：  0.98
包层不圆度：  1.43
芯包同心度：  0.28
None
2017-04-01 10:31:01,114-ERROR-_emitCVShowResult:清晰度指数：  6.94
纤芯直径：    62.33
包层直径：    116.15
纤芯不圆度：  1.08
包层不圆度：  1.46
芯包同心度：  0.26
None
2017-04-01 10:31:12,732-ERROR-_emitCVShowResult:清晰度指数：  6.95
纤芯直径：    62.33
包层直径：    116.16
纤芯不圆度：  1.10
包层不圆度：  1.44
芯包同心度：  0.27
None
2017-04-07 15:30:31,753-ERROR-_emitCVShowResult:清晰度指数：  3.46
纤芯直径：    8.97
包层直径：    124.40
纤芯不圆度：  0.03
包层不圆度：  0.76
芯包同心度：  0.30
None
